Traceback (most recent call last):
  File "tests/Python_Errors/IndexError.py", line 2, in <module>
    print(list[4]) #list index out of range
IndexError: list index out of range

