Traceback (most recent call last):
  File "tests/Python_Errors/KeyError.py", line 2, in <module>
    print(dir[3])
KeyError: 3

